Workbook
Name Slicer_DIVISION_DESCRIPTION: #N/A

Sheet Pivot Table
A3: DIVISION DESCRIPTION | B3: Sum of TOTAL BUDGETED AMOUNT
A4: Patrol Services | B4: 1224603400
A5: Chicago Fire Department | B5: 556547794
A6: Chicago-O'Hare International Airport | B6: 197854959
A7: Bureau of Operations and Distribution | B7: 169911417
A8: Bureau of Counter-Terrorism | B8: 143287614
A9: Bureau of Sanitation | B9: 127338664
A10: Division of In-House Construction | B10: 94835261
A11: Office of Emergency Management and Communications | B11: 81824516
A12: Chicago Public Library | B12: 77548650
A13: Bureau of Detectives | B13: 68753448
A14: Grand Total | B14: 2742505723

Sheet Dashboard
A1: CHICAGO CITY BUDGET DASHBOARD
A2: KPI Summary
A3: Total Budget | B3: =SUM('Raw Data'!V:V) -> 3910809184
A4: Total Positions | B4: =SUM('Raw Data'!T:T) -> 7186
A5: AVG. Pay Rate | B5: =AVERAGE('Raw Data'!U:U) -> 100052.25
A6: Highest Salary | B6: =MAX('Raw Data'!V:V) -> 238969296
A7: Top 10 Divisions
A8: Division | B8: Total Budget | C8: Headcount | D8: Cost Per Position | E8: % Of Budget
A9: Patrol Services | B9: =SUMIF('Raw Data'!I:I,"Patrol Services",'Raw Data'!V:V) -> 1224603400 | C9: =COUNTIF('Raw Data'!I:I,"Patrol Services") -> 102 | D9: =B9/C9 -> 12005916 | E9: =B9/SUM('Raw Data'!V:V) -> 0.313133
A10: Chicago Fire Department | B10: =SUMIF('Raw Data'!I:I,"Chicago Fire Department",'Raw Data'!V:V) -> 556547794 | C10: =COUNTIF('Raw Data'!I:I,"Chicago Fire Department") -> 406 | D10: =B10/C10 -> 1370807.4 | E10: =B10/SUM('Raw Data'!V:V) -> 0.14231014
A11: Chicago-O'Hare International Airport | B11: =SUMIF('Raw Data'!I:I,"Chicago-O'Hare International Airport",'Raw Data'!V:V) -> 197854959 | C11: =COUNTIF('Raw Data'!I:I,"Chicago-O'Hare International Airport") -> 573 | D11: =B11/C11 -> 345296.61 | E11: =B11/SUM('Raw Data'!V:V) -> 0.050591821
A12: Bureau of Operations and Distribution | B12: =SUMIF('Raw Data'!I:I,"Bureau of Operations and Distribution",'Raw Data'!V:V) -> 169911417 | C12: =COUNTIF('Raw Data'!I:I,"Bureau of Operations and Distribution") -> 165 | D12: =B12/C12 -> 1029766.2 | E12: =B12/SUM('Raw Data'!V:V) -> 0.043446614
A13: Bureau of Counter-Terrorism | B13: =SUMIF('Raw Data'!I:I,"Bureau of Counter-Terrorism",'Raw Data'!V:V) -> 143287614 | C13: =COUNTIF('Raw Data'!I:I,"Bureau of Counter-Terrorism") -> 259 | D13: =B13/C13 -> 553234.03 | E13: =B13/SUM('Raw Data'!V:V) -> 0.036638866
A14: Bureau of Sanitation | B14: =SUMIF('Raw Data'!I:I,"Bureau of Sanitation",'Raw Data'!V:V) -> 127338664 | C14: =COUNTIF('Raw Data'!I:I,"Bureau of Sanitation") -> 88 | D14: =B14/C14 -> 1447030.3 | E14: =B14/SUM('Raw Data'!V:V) -> 0.032560695
A15: Division of In-House Construction | B15: =SUMIF('Raw Data'!I:I,"Division of In-House Construction",'Raw Data'!V:V) -> 94835261 | C15: =COUNTIF('Raw Data'!I:I,"Division of In-House Construction") -> 124 | D15: =B15/C15 -> 764800.49 | E15: =B15/SUM('Raw Data'!V:V) -> 0.024249524
A16: Office of Emergency Management and Communications | B16: =SUMIF('Raw Data'!I:I,"Office of Emergency Management and Communications",'Raw Data'!V:V) -> 81824516 | C16: =COUNTIF('Raw Data'!I:I,"Office of Emergency Management and Communications") -> 200 | D16: =B16/C16 -> 409122.58 | E16: =B16/SUM('Raw Data'!V:V) -> 0.020922656
A17: Chicago Public Library | B17: =SUMIF('Raw Data'!I:I,"Chicago Public Library",'Raw Data'!V:V) -> 77548650 | C17: =COUNTIF('Raw Data'!I:I,"Chicago Public Library") -> 196 | D17: =B17/C17 -> 395656.38 | E17: =B17/SUM('Raw Data'!V:V) -> 0.019829311
A18: Bureau of Detectives | B18: =SUMIF('Raw Data'!I:I,"Bureau of Detectives",'Raw Data'!V:V) -> 68753448 | C18: =COUNTIF('Raw Data'!I:I,"Bureau of Detectives") -> 165 | D18: =B18/C18 -> 416687.56 | E18: =B18/SUM('Raw Data'!V:V) -> 0.017580364
A51: DIVISION DESCRIPTION | B51: Sum of TOTAL BUDGETED AMOUNT | C51: Sum of TOTAL BUDGETED UNIT
A52: Patrol Services | B52: 1224603400 | C52: 71693
A53: Chicago Fire Department | B53: 556547794 | C53: 5123
A54: Chicago-O'Hare International Airport | B54: 197854959 | C54: 319472
A55: Bureau of Operations and Distribution | B55: 169911417 | C55: 1365248
A56: Bureau of Counter-Terrorism | B56: 143287614 | C56: 21611
A57: Bureau of Sanitation | B57: 127338664 | C57: 57299
A58: Division of In-House Construction | B58: 94835261 | C58: 454601
A59: Office of Emergency Management and Communications | B59: 81824516 | C59: 204480
A60: Chicago Public Library | B60: 77548650 | C60: 355442
A61: Bureau of Detectives | B61: 68753448 | C61: 12922
A62: Bureau of Fleet Operations | B62: 68737489 | C62: 608
A63: Office of Constitutional Policing and Reform | B63: 65833298 | C63: 25553
... A211: Grand Total | B211: 3910809184 | C211: 3270432

Sheet Raw Data
A1: FUND TYPE | B1: DEPARTMENT CODE | C1: DEPARTMENT DESCRIPTION | D1: FUND CODE | E1: FUND DESCRIPTION | F1: ORGANIZATION CODE | G1: ORGANIZATION DESCRIPTION | H1: DIVISION CODE | I1: DIVISION DESCRIPTION | J1: SECTION CODE | K1: SECTION DESCRIPTION | L1: SUBSECTION CODE | M1: SUB-SECTION DESCRIPTION | N1: SCHEDULE / GRADE | O1: BARGAINING UNIT | P1: TITLE CODE | Q1: TITLE DESCRIPTION | R1: BUDGETED UNIT | S1: TOTAL BUDGETED UNIT | T1: POSITION CONTROL | U1: BUDGETED PAY RATE | V1: TOTAL BUDGETED AMOUNT | W1: Cost Per Position | X1: % Of Total Budget
A2: LOCAL | B2: 1 | C2: Office of the Mayor | D2: 100 | E2: Corporate Fund | F2: 1005 | G2: Office of the Mayor | H2: 2005 | I2: Office of the Mayor | J2: 3005 | K2: Executive | L2: 0 | N2: 1 00 | O2: 9 | P2: 9901 | Q2: Mayor | R2: Annual | S2: 1 | T2: 1 | U2: 221052 | V2: 221052 | W2: =V2/T2 -> 221052 | X2: =V2/SUM($V$2:$V$10000) -> 5.6523341e-05
A3: LOCAL | B3: 1 | C3: Office of the Mayor | D3: 100 | E3: Corporate Fund | F3: 1005 | G3: Office of the Mayor | H3: 2005 | I3: Office of the Mayor | J3: 3005 | K3: Executive | L3: 0 | N3: 1 00 | O3: 9 | P3: 9877 | Q3: Director - Mayor's Office | R3: Annual | S3: 1 | T3: 1 | U3: 142272 | V3: 142272
A4: LOCAL | B4: 1 | C4: Office of the Mayor | D4: 100 | E4: Corporate Fund | F4: 1005 | G4: Office of the Mayor | H4: 2005 | I4: Office of the Mayor | J4: 3005 | K4: Executive | L4: 0 | N4: 1 00 | O4: 9 | P4: 9875 | Q4: Senior Project Manager - Mayor's Office | R4: Annual | S4: 1 | T4: 1 | U4: 123600 | V4: 123600
A5: LOCAL | B5: 1 | C5: Office of the Mayor | D5: 100 | E5: Corporate Fund | F5: 1005 | G5: Office of the Mayor | H5: 2005 | I5: Office of the Mayor | J5: 3005 | K5: Executive | L5: 0 | N5: 1 00 | O5: 9 | P5: 9869 | Q5: Senior Advisor to the Mayor | R5: Annual | S5: 1 | T5: 1 | U5: 195000 | V5: 195000
A6: LOCAL | B6: 1 | C6: Office of the Mayor | D6: 100 | E6: Corporate Fund | F6: 1005 | G6: Office of the Mayor | H6: 2005 | I6: Office of the Mayor | J6: 3005 | K6: Executive | L6: 0 | N6: 1 00 | O6: 0 | P6: 9637 | Q6: Administrative Assistant | R6: Annual | S6: 1 | T6: 1 | U6: 110464 | V6: 110464
A7: LOCAL | B7: 1 | C7: Office of the Mayor | D7: 100 | E7: Corporate Fund | F7: 1005 | G7: Office of the Mayor | H7: 2005 | I7: Office of the Mayor | J7: 3006 | K7: Correspondence | L7: 0 | N7: 1 00 | O7: 9 | P7: 9874 | Q7: Project Manager - Mayor's Office | R7: Annual | S7: 1 | T7: 1 | U7: 106632 | V7: 106632
A8: LOCAL | B8: 1 | C8: Office of the Mayor | D8: 100 | E8: Corporate Fund | F8: 1005 | G8: Office of the Mayor | H8: 2005 | I8: Office of the Mayor | J8: 3007 | K8: Scheduling and Advance | L8: 0 | N8: 1 00 | O8: 9 | P8: 9870 | Q8: Advance | R8: Annual | S8: 1 | T8: 1 | U8: 74592 | V8: 74592
A9: LOCAL | B9: 1 | C9: Office of the Mayor | D9: 100 | E9: Corporate Fund | F9: 1005 | G9: Office of the Mayor | H9: 2005 | I9: Office of the Mayor | J9: 3007 | K9: Scheduling and Advance | L9: 0 | N9: 1 00 | O9: 9 | P9: 9855 | Q9: Assistant Director - Mayor's Office | R9: Annual | S9: 1 | T9: 1 | U9: 90048 | V9: 90048
A10: LOCAL | B10: 1 | C10: Office of the Mayor | D10: 100 | E10: Corporate Fund | F10: 1005 | G10: Office of the Mayor | H10: 2005 | I10: Office of the Mayor | J10: 3010 | K10: Administrative | L10: 0 | N10: 1 00 | O10: 9 | P10: 9899 | Q10: Chief of Staff | R10: Annual | S10: 1 | T10: 1 | U10: 217044 | V10: 217044
A11: LOCAL | B11: 1 | C11: Office of the Mayor | D11: 100 | E11: Corporate Fund | F11: 1005 | G11: Office of the Mayor | H11: 2005 | I11: Office of the Mayor | J11: 3010 | K11: Administrative | L11: 0 | N11: 1 00 | O11: 9 | P11: 9898 | Q11: Deputy Chief of Staff | R11: Annual | S11: 1 | T11: 1 | U11: 183180 | V11: 183180
A12: LOCAL | B12: 1 | C12: Office of the Mayor | D12: 100 | E12: Corporate Fund | F12: 1005 | G12: Office of the Mayor | H12: 2005 | I12: Office of the Mayor | J12: 3010 | K12: Administrative | L12: 0 | N12: 1 00 | O12: 9 | P12: 9889 | Q12: First Deputy Chief of Staff | R12: Annual | S12: 1 | T12: 1 | U12: 197760 | V12: 197760
A13: LOCAL | B13: 1 | C13: Office of the Mayor | D13: 100 | E13: Corporate Fund | F13: 1005 | G13: Office of the Mayor | H13: 2005 | I13: Office of the Mayor | J13: 3010 | K13: Administrative | L13: 0 | N13: 1 00 | O13: 9 | P13: 9877 | Q13: Director - Mayor's Office | R13: Annual | S13: 1 | T13: 1 | U13: 135912 | V13: 135912
A14: LOCAL | B14: 1 | C14: Office of the Mayor | D14: 100 | E14: Corporate Fund | F14: 1005 | G14: Office of the Mayor | H14: 2005 | I14: Office of the Mayor | J14: 3010 | K14: Administrative | L14: 0 | N14: 1 00 | O14: 9 | P14: 9874 | Q14: Project Manager - Mayor's Office | R14: Annual | S14: 1 | T14: 1 | U14: 92172 | V14: 92172
... A147: LOCAL | B147: 3 | C147: Office of Inspector General | D147: 100 | E147: Corporate Fund | F147: 1005 | G147: Office of Inspector General | H147: 2005 | I147: Office of Inspector General | J147: 3045 | K147: Information Technology and Analytics | L147: 0 | N147: X 33 | O147: 0 | P147: 1717 | Q147: Chief Data and Information Analyst | R147: Annual | S147: 1 | T147: 1 | U147: 153384 | V147: 153384
A148: LOCAL | B148: 3 | C148: Office of Inspector General | D148: 100 | E148: Corporate Fund | F148: 1005 | G148: Office of Inspector General | H148: 2005 | I148: Office of Inspector General | J148: 3045 | K148: Information Technology and Analytics | L148: 0 | N148: BX 17 | O148: 10 | P148: 06M3 | Q148: Web Developer/Administrator (OIG) | R148: Annual | S148: 1 | T148: 1 | U148: 103488 | V148: 103488
A149: LOCAL | B149: 3 | C149: Office of Inspector General | D149: 100 | E149: Corporate Fund | F149: 1005 | G149: Office of Inspector General | H149: 2005 | I149: Office of Inspector General | J149: 3045 | K149: Information Technology and Analytics | L149: 0 | N149: GY 09 | O149: 20 | P149: 06A7 | Q149: IT Security Analyst-IG | R149: Annual | S149: 1 | T149: 1 | U149: 97332 | V149: 97332
A150: LOCAL | B150: 3 | C150: Office of Inspector General | D150: 100 | E150: Corporate Fund | F150: 1005 | G150: Office of Inspector General | H150: 2005 | I150: Office of Inspector General | J150: 3045 | K150: Information Technology and Analytics | L150: 0 | N150: BX 17 | O150: 10 | P150: 06A4 | Q150: Data Services Administrator-Excluded | R150: Annual | S150: 1 | T150: 1 | U150: 85128 | V150: 85128
A151: LOCAL | B151: 3 | C151: Office of Inspector General | D151: 100 | E151: Corporate Fund | F151: 1005 | G151: Office of Inspector General | H151: 2005 | I151: Office of Inspector General | J151: 3045 | K151: Information Technology and Analytics | L151: 0 | N151: BX 13 | O151: 10 | P151: 645 | Q151: Technical Support Administrator - IG | R151: Annual | S151: 1 | T151: 1 | U151: 60660 | V151: 60660
A152: LOCAL | B152: 3 | C152: Office of Inspector General | D152: 100 | E152: Corporate Fund | F152: 1005 | G152: Office of Inspector General | H152: 2005 | I152: Office of Inspector General | J152: 3045 | K152: Information Technology and Analytics | L152: 0 | N152: GY 09 | O152: 10 | P152: 641 | Q152: Forensic Data Analyst | R152: Annual | S152: 1 | T152: 1 | U152: 101628 | V152: 101628
A153: LOCAL | B153: 3 | C153: Office of Inspector General | D153: 100 | E153: Corporate Fund | F153: 1005 | G153: Office of Inspector General | H153: 2005 | I153: Office of Inspector General | J153: 3045 | K153: Information Technology and Analytics | L153: 0 | N153: GY 09 | O153: 10 | P153: 641 | Q153: Forensic Data Analyst | R153: Annual | S153: 2 | T153: 1 | U153: 97332 | V153: 194664
A154: LOCAL | B154: 3 | C154: Office of Inspector General | D154: 100 | E154: Corporate Fund | F154: 1005 | G154: Office of Inspector General | H154: 2005 | I154: Office of Inspector General | J154: 3045 | K154: Information Technology and Analytics | L154: 0 | N154: GY 09 | O154: 10 | P154: 641 | Q154: Forensic Data Analyst | R154: Annual | S154: 1 | T154: 1 | U154: 89112 | V154: 89112
A155: LOCAL | B155: 3 | C155: Office of Inspector General | D155: 100 | E155: Corporate Fund | F155: 1005 | G155: Office of Inspector General | H155: 2005 | I155: Office of Inspector General | J155: 3045 | K155: Information Technology and Analytics | L155: 0 | N155: 1 00 | O155: 0 | P155: 15 | Q155: Schedule Salary Adjustments | R155: Annual | S155: 0 | T155: 0 | U155: 44675 | V155: 44675
A156: LOCAL | B156: 5 | C156: Office of Budget and Management | D156: 100 | E156: Corporate Fund | F156: 1005 | G156: Office of Budget and Management | H156: 2005 | I156: Office of Budget and Management | J156: 3005 | K156: Administration | L156: 0 | N156: 1 00 | O156: 9 | P156: 9905 | Q156: Budget Director | R156: Annual | S156: 1 | T156: 1 | U156: 218280 | V156: 218280
A157: LOCAL | B157: 5 | C157: Office of Budget and Management | D157: 100 | E157: Corporate Fund | F157: 1005 | G157: Office of Budget and Management | H157: 2005 | I157: Office of Budget and Management | J157: 3005 | K157: Administration | L157: 0 | N157: X 31 | O157: 0 | P157: 9868 | Q157: First Deputy Budget Director | R157: Annual | S157: 1 | T157: 1 | U157: 199800 | V157: 199800
A158: LOCAL | B158: 5 | C158: Office of Budget and Management | D158: 100 | E158: Corporate Fund | F158: 1005 | G158: Office of Budget and Management | H158: 2005 | I158: Office of Budget and Management | J158: 3005 | K158: Administration | L158: 0 | N158: X 31 | O158: 9 | P158: 1120 | Q158: Managing Deputy Budget Director | R158: Annual | S158: 1 | T158: 1 | U158: 188400 | V158: 188400
A159: LOCAL | B159: 5 | C159: Office of Budget and Management | D159: 100 | E159: Corporate Fund | F159: 1005 | G159: Office of Budget and Management | H159: 2005 | I159: Office of Budget and Management | J159: 3005 | K159: Administration | L159: 0 | N159: BX 16 | O159: 10 | P159: 802 | Q159: Executive Administrative Assistant II | R159: Annual | S159: 1 | T159: 1 | U159: 124584 | V159: 124584
A160: LOCAL | B160: 5 | C160: Office of Budget and Management | D160: 100 | E160: Corporate Fund | F160: 1005 | G160: Office of Budget and Management | H160: 2005 | I160: Office of Budget and Management | J160: 3005 | K160: Administration | L160: 0 | N160: BX 16 | O160: 10 | P160: 802 | Q160: Executive Administrative Assistant II | R160: Annual | S160: 1 | T160: 1 | U160: 94332 | V160: 94332
A161: LOCAL | B161: 5 | C161: Office of Budget and Management | D161: 100 | E161: Corporate Fund | F161: 1005 | G161: Office of Budget and Management | H161: 2005 | I161: Office of Budget and Management | J161: 3005 | K161: Administration | L161: 0 | N161: BX 18 | O161: 20 | P161: 394 | Q161: Administrative Manager | R161: Annual | S161: 1 | T161: 1 | U161: 93384 | V161: 93384
A162: LOCAL | B162: 5 | C162: Office of Budget and Management | D162: 100 | E162: Corporate Fund | F162: 1005 | G162: Office of Budget and Management | H162: 2005 | I162: Office of Budget and Management | J162: 3005 | K162: Administration | L162: 0 | N162: 1 00 | O162: 0 | P162: 15 | Q162: Schedule Salary Adjustments | R162: Annual | S162: 0 | T162: 0 | U162: 10990 | V162: 10990
... A178: LOCAL | B178: 5 | C178: Office of Budget and Management | D178: 100 | E178: Corporate Fund | F178: 1005 | G178: Office of Budget and Management | H178: 2005 | I178: Office of Budget and Management | J178: 3015 | K178: Strategic Communications | L178: 0 | N178: 1 00 | O178: 0 | P178: 15 | Q178: Schedule Salary Adjustments | R178: Annual | S178: 0 | T178: 0 | U178: 17530 | V178: 17530
A179: LOCAL | B179: 5 | C179: Office of Budget and Management | D179: 100 | E179: Corporate Fund | F179: 1005 | G179: Office of Budget and Management | H179: 2005 | I179: Office of Budget and Management | J179: 3160 | K179: Workforce Management and Technology | L179: 4160 | M179: Compensation Control | N179: X 32 | O179: 9 | P179: 9684 | Q179: Deputy Director | R179: Annual | S179: 1 | T179: 1 | U179: 167964 | V179: 167964
A180: LOCAL | B180: 5 | C180: Office of Budget and Management | D180: 100 | E180: Corporate Fund | F180: 1005 | G180: Office of Budget and Management | H180: 2005 | I180: Office of Budget and Management | J180: 3160 | K180: Workforce Management and Technology | L180: 4160 | M180: Compensation Control | N180: BX 16 | O180: 10 | P180: 1333 | Q180: Compensation Specialist | R180: Annual | S180: 1 | T180: 1 | U180: 124584 | V180: 124584
A181: LOCAL | B181: 5 | C181: Office of Budget and Management | D181: 100 | E181: Corporate Fund | F181: 1005 | G181: Office of Budget and Management | H181: 2005 | I181: Office of Budget and Management | J181: 3160 | K181: Workforce Management and Technology | L181: 4160 | M181: Compensation Control | N181: 1 00 | O181: 0 | P181: 15 | Q181: Schedule Salary Adjustments | R181: Annual | S181: 0 | T181: 0 | U181: 1887 | V181: 1887
A182: LOCAL | B182: 5 | C182: Office of Budget and Management | D182: 100 | E182: Corporate Fund | F182: 1005 | G182: Office of Budget and Management | H182: 2005 | I182: Office of Budget and Management | J182: 3160 | K182: Workforce Management and Technology | L182: 4165 | M182: Applications | N182: X 32 | O182: 9 | P182: 9684 | Q182: Deputy Director | R182: Annual | S182: 1 | T182: 1 | U182: 167964 | V182: 167964
A183: LOCAL | B183: 5 | C183: Office of Budget and Management | D183: 100 | E183: Corporate Fund | F183: 1005 | G183: Office of Budget and Management | H183: 2005 | I183: Office of Budget and Management | J183: 3160 | K183: Workforce Management and Technology | L183: 4165 | M183: Applications | N183: GY 09 | O183: 20 | P183: 647 | Q183: Senior Programmer Analyst - Excluded | R183: Annual | S183: 1 | T183: 1 | U183: 115992 | V183: 115992
A184: LOCAL | B184: 5 | C184: Office of Budget and Management | D184: 100 | E184: Corporate Fund | F184: 1005 | G184: Office of Budget and Management | H184: 2005 | I184: Office of Budget and Management | J184: 3160 | K184: Workforce Management and Technology | L184: 4165 | M184: Applications | N184: 1 00 | O184: 0 | P184: 15 | Q184: Schedule Salary Adjustments | R184: Annual | S184: 0 | T184: 0 | U184: 1887 | V184: 1887
A185: LOCAL | B185: 5 | C185: Office of Budget and Management | D185: 100 | E185: Corporate Fund | F185: 1005 | G185: Office of Budget and Management | H185: 2005 | I185: Office of Budget and Management | J185: 3160 | K185: Workforce Management and Technology | L185: 4170 | M185: Data Analytics | N185: X 32 | O185: 9 | P185: 9656 | Q185: Deputy Budget Director | R185: Annual | S185: 1 | T185: 1 | U185: 175512 | V185: 175512
A186: LOCAL | B186: 5 | C186: Office of Budget and Management | D186: 100 | E186: Corporate Fund | F186: 1005 | G186: Office of Budget and Management | H186: 2005 | I186: Office of Budget and Management | J186: 3160 | K186: Workforce Management and Technology | L186: 4170 | M186: Data Analytics | N186: GY 08 | O186: 20 | P186: 1141 | Q186: Principal Operations Analyst | R186: Annual | S186: 2 | T186: 1 | U186: 82884 | V186: 165768
A187: LOCAL | B187: 5 | C187: Office of Budget and Management | D187: 100 | E187: Corporate Fund | F187: 1005 | G187: Office of Budget and Management | H187: 2005 | I187: Office of Budget and Management | J187: 3160 | K187: Workforce Management and Technology | L187: 4170 | M187: Data Analytics | N187: G 09 | O187: 3 | P187: 1140 | Q187: Chief Operations Analyst | R187: Annual | S187: 1 | T187: 1 | U187: 117636 | V187: 117636
...
